Workbook

Sheet Export Summary
B3: This document was exported from Numbers. Each table was converted to an Excel worksheet. All other objects on each Numbers sheet were placed on separate worksheets. Please be aware that formula calculations may differ in Excel.
B7: Numbers Sheet Name | C7: Numbers Table Name | D7: Excel Worksheet Name
B9: BUDGET
C10: Table 1 | D10: BUDGET
B11: VE
C12: Table 1 | D12: VE
B13: SERVICES
C14: Table 1 | D14: SERVICES
B15: NOTES
C16: Table 1 | D16: NOTES

Sheet BUDGET
A1: Farber-Haines Residence
A2: Landscape Construction Work Outline 1.0
A3: Site Plan dated 03.17.26
A5: DESCRIPTION | B5: QTY | C5: UNIT | D5: UNIT PRICE | E5: PRICE | F5: UPDATED | H5: TYPE | J5: TYPE | K5: COMPANY
A7: SITE PREP 2.0 | E7: {=SUM(E8:E11)} -> 8500 | F7: 46069
A8: Crew / Trailer / Machinery Mobilization | B8: 1 | C8: ea | D8: 1500 | E8: {=D8*B8} -> 1500 | H8: Allowance | J8: Allowance 10.0 | K8: LHLC
A9: Debris Hauling & Disposal | B9: 1 | C9: ea | D9: 2000 | E9: {=D9*B9} -> 2000 | H9: Allowance | J9: Allowance 10.0 | K9: LHLC
A10: Final Site Property Cleanup, Detailing - ALLOWANCE 10.0 | B10: 1 | C10: ea | D10: 5000 | E10: {=D10*B10} -> 5000 | H10: Allowance | J10: Allowance 10.0 | K10: LHLC
A12: DRAINAGE ALLOWANCE 10.0 (PENDING CIVIL DESIGN) | E12: {=SUM(E13:E16)} -> 20300 | F12: 46069
A13: 12” Area Drain / Elbow / Fittings @ Downspouts | B13: 9 | C13: ea | D13: {=416.67*1.2} -> 500.004 | E13: 4500 | H13: Allowance | J13: Allowance 10.0 | K13: LHLC
A14: Downspout Extension w/ Popup Fitting | B14: 135 | C14: lf | D14: 80 | E14: {=D14*B14} -> 10800
A15: Site Drainage ALLOWANCE 10.0 | B15: 1 | C15: ea | D15: 5000 | E15: {=D15*B15} -> 5000 | H15: Allowance | J15: Allowance 10.0 | K15: LHLC
A17: WALLS - ALLOWANCE 10.0 | E17: {=SUM(E18:E21)} -> 55368
A18: Concrete Wall (0’-8” W x 2’-0”H) w/ Spread Footer | B18: 52 | C18: lf | D18: {=340*1.1} -> 374 | E18: {=B18*D18} -> 19448
A19: Concrete Pump | B19: 4 | C19: ea | D19: 605 | E19: {=B19*D19} -> 2420
A20: Driveway Wall - Steel (~3’-0” H max.) | B20: 45 | C20: lf | D20: 300 | E20: {=B20*D20} -> 13500
A21: Concrete Landscape Block Wall w/ French Drain w/ Cap (4-0” H) | B21: 160 | C21: ff | D21: 125 | E21: {=B21*D21} -> 20000
A22: Cost Savings Options 12.0
A23: Remove Driveway Wall | B23: 1 | C23: ea | D23: {=-E20} -> -13500 | E23: {=B23*D23} -> -13500
A25: GRADING - ALLOWANCE 10.0 | E25: {=SUM(E26:E27)} -> 8500 | F25: 46069
A26: Fine Grading - ALLOWANCE 10.0 | B26: 1 | C26: ea | D26: 8500 | E26: {=D26*B26} -> 8500 | H26: Allowance | J26: Allowance 10.0 | K26: LHLC
A28: BOULDERS 3.0 | E28: {=SUM(E29:E31)} -> 20560 | F28: 46069
A29: Boulders - Granite, Avg 1.5 ton 18”x18”x36” | B29: 30 | C29: ton | D29: 650 | E29: {=D29*B29} -> 19500 | H29: Allowance | J29: Allowance 10.0 | K29: LHLC
A30: Delivery - Boulders | B30: {=B29/15} -> 2 | C30: ea | D30: 530 | E30: {=D30*B30} -> 1060 | H30: Allowance | J30: Allowance 10.0 | K30: LHLC
A32: POOL - ALLOWANCE 9.0 + 10.0 | E32: {=SUM(E33:E52)} -> 309400 | F32: 46069
A33: Pool (10’-0” x 25’-0” Custom Shotcrete Shell w/ Equipment) | B33: 1 | C33: ea | D33: 225000 | E33: {=B33*D33} -> 225000
A34: Permit | B34: 1 | C34: ea | D34: {=SUM(E33)*0.04} -> 9000 | E34: {=B34*D34} -> 9000 | L34: Allowance
A35: Preparation + Finish:
A36: Surveying and Staking | B36: 1 | C36: ea | D36: 500 | E36: {=B36*D36} -> 500 | L36: Allowance
A37: Excavation and Backfill | B37: 1 | C37: ea | D37: 25000 | E37: {=B37*D37} -> 25000 | L37: Allowance
A38: Trenching for Pool Plumbing (2’ Depth) | B38: 80 | C38: lf | D38: 35 | E38: {=D38*B38} -> 2800 | H38: Allowance | J38: Allowance 10.0 | K38: LHLC
A39: Core Drill + LinkSeal to Mech Room | B39: 1 | C39: ea | D39: 4500 | E39: {=B39*D39} -> 4500 | L39: Excluded
A40: Perimeter Drain Pool | B40: 80 | C40: lf | D40: 70 | E40: {=D40*B40} -> 5600
A41: Bonding of Patio | B41: 1 | C41: ea | D41: 1800 | E41: {=B41*D41} -> 1800 | L41: Allowance
A42: Auto Cover Brackets - Design and Material TBD | B42: 1 | C42: ea | D42: 12000 | E42: {=B42*D42} -> 12000
A43: Utilities:
A44: Energy Offsets Engineering Consultant, TBD | B44: 1 | C44: ea | D44: 3000 | E44: {=B44*D44} -> 3000 | L44: Allowance
A45: Electrical Wiring to Equipment In Mech Room | B45: 1 | C45: ea | D45: 15600 | E45: {=B45*D45} -> 15600 | L45: Allowance
A46: Plumbing and Autofill Hookups to Equipment | B46: 1 | C46: ea | D46: 3600 | E46: {=B46*D46} -> 3600 | L46: Allowance
A47: Internet Hookup to Equipment | B47: 1 | C47: ea | D47: 1000 | E47: {=B47*D47} -> 1000 | L47: Allowance
...

Sheet VE
B1: Farber-Haines Residence
B2: Value Engineering Options
B3: Site Plan dated 03.17.26
B5: Scope of Work
B6: DESCRIPTION | C6: SD1 | D6: PB 1 | E6: Difference | F6: NOTES | G6: VALUE ENGINEERING Options | H6: VALUE ENGINEERING Savings | I6: TYPE | J6: DETAIL | Q6: INVOICED + TRENDING | S6: INVOICE 01 - 2023.09.18 | V6: INVOICE 02 - 2023.10.19 | Y6: INVOICE 03 - 2023.11.13 | AB6: INVOICE 04 - 2023.11.29 | AE6: INVOICE 05 - 2023.12.04
B7: DATE: | C7: 46098 | D7: 46072 | G7: 46098 | H7: 46098
B8: Site Prep | C8: {='BUDGET'!E7} -> 8500 | D8: 103625 | E8: {=D8-C8} -> 95125 | F8: - | G8: - | H8: -
B9: Drainage | C9: {='BUDGET'!E12} -> 20300 | D9: 135606.25 | E9: {=D9-C9} -> 115306.25 | F9: - | G9: Civil Design TBD | H9: -
B10: Walls | C10: {='BUDGET'!E17} -> 55368 | D10: 18791.85 | E10: {=D10-C10} -> -36576.15 | F10: - | G10: Change to Concrete Walls | H10: {=#REF!}
B11: Grading | C11: {='BUDGET'!E25} -> 8500 | D11: 31000 | E11: {=D11-C11} -> 22500 | F11: - | G11: - | H11: - | I11: Allowance
B12: Boulders | C12: {='BUDGET'!E28} -> 20560 | D12: 63050 | E12: {=D12-C12} -> 42490 | F12: - | G12: - | H12: - | I12: Allowance
B13: Pool | C13: {='BUDGET'!E32} -> 309400 | D13: 850370.15 | E13: {=D13-C13} -> 540970.15 | F13: - | G13: Change to Fiberglass Pool Shell | H13: {='BUDGET'!E54} -> -87000
B14: Spa | E14: {=D14-C14} -> 0 | G14: Eliminate Spa | H14: {=#REF!}
B15: Flatwork | C15: {='BUDGET'!E56} -> 88361.85 | D15: 387096.7 | E15: {=D15-C15} -> 298734.85 | F15: - | G15: - | H15: - | I15: Bid
B16: Irrigation | C16: {='BUDGET'!E75} -> 39475 | D16: 106750 | E16: {=D16-C16} -> 67275 | F16: - | G16: - | H16: -
B17: Groundcovers | C17: {='BUDGET'!E82} -> 138138.15 | D17: 263229.5 | E17: {=D17-C17} -> 125091.35 | F17: - | G17: Reduce Backyard Berm & Edging | H17: {=SUM('BUDGET'!E97:E104)} -> -19602.083 | I17: Allowance
B18: Planting | C18: {='BUDGET'!E106} -> 118753.18 | D18: 585164.5 | E18: {=D18-C18} -> 466411.32 | F18: - | G18: Reduce Backyard Berm | H18: {=SUM('BUDGET'!E120:E123)} -> -6661.9367
B19: Driveway | C19: {='BUDGET'!E125} -> 60200.5 | D19: 157050 | E19: {=D19-C19} -> 96849.5 | F19: - | G19: - | H19: -
B20: Auto Gate* | C20: {='BUDGET'!E185} -> 56500 | D20: 62300 | E20: {=D20-C20} -> 5800 | F20: - | G20: Remove | H20: {=#REF!} | I20: Allowance
B21: Fencing | C21: {='BUDGET'!E132} -> 28268.25 | D21: 98696.125 | E21: {=D21-C21} -> 70427.875 | F21: - | G21: Reduce Front Yard | H21: {='BUDGET'!E138} -> -10254.75 | I21: Bid | J21: 3/L4.20
B22: Lighting | C22: {='BUDGET'!E140} -> 27284 | D22: 52955 | E22: {=D22-C22} -> 25671 | F22: - | G22: Reduce Qty | H22: {='BUDGET'!E147} -> -9003.72 | I22: Allowance
B23: Raised Planters | C23: {='BUDGET'!E149} -> 29350 | G23: Reduce | H23: 0
B24: General Allowances | C24: {='BUDGET'!E158} -> 25500 | G24: - | H24: -
B25: SUBTOTAL | C25: {=SUM(C8:C24)} -> 1034458.9 | D25: {=SUM(D8:D22)} -> 2915685.1 | E25: {=SUM(E8:E22)} -> 1936076.1 | G25: - | H25: {=C25+SUM(H8:H24)}
B26: Project Management Fee | C26: {=C25*0.2} -> 206891.79 | D26: {=D25*0.2} -> 583137.02 | E26: {=D26-C26} -> 376245.23 | G26: - | H26: {=H25*0.2}
B27: Project Foreman Fee | C27: {=C25*0.015} -> 15516.884 | E27: {=D27-C27} -> -15516.884 | G27: - | H27: {=H25*0.015}
B28: PROJECT LIABILITY INSURANCE | C28: {=C25*0.0085} -> 8792.9009 | D28: {=D25*0.005} -> 14578.425 | E28: {=D28-C28} -> 5785.5245 | G28: - | H28: {=H25*0.0085}
B29: TOTAL PROJECT COSTS | C29: {=SUM(C25:C28)} -> 1265660.5 | D29: {=SUM(D25:D28)} -> 3513400.5 | E29: {=SUM(E25:E28)} -> 2302590 | G29: - | H29: {=SUM(H25:H28)}
B32: Add OPTIONS
B33: DESCRIPTION | C33: SD1 | D33: Progress | E33: Difference | F33: NOTES | G33: VALUE ENGINEERING Options | H33: VALUE ENGINEERING Savings
B34: DATE: | C34: 46098 | D34: Tbd | G34: 46098 | H34: 46098
B35: Furnishings Shade Parasol | C35: {='BUDGET'!E165} -> 24055.24 | D35: 0 | E35: {=D35-C35} -> -24055.24 | F35: - | G35: - | H35: -
B36: Fire Feature* | C36: {='BUDGET'!E197} -> 15500 | D36: 58390 | E36: {=D36-C36} -> 42890 | F36: - | G36: Design TBD | H36: - | I36: Allowance
B37: Outdoor Kitchen | C37: {='BUDGET'!E201} -> 24000 | D37: 51400 | E37: {=D37-C37} -> 27400 | F37: - | G37: Design TBD | H37: -
B38: Trench Drain at Driveway | C38: {='BUDGET'!E215} -> 8375 | E38: {=D38-C38} -> -8375 | G38: Design TBD | H38: -
B39: Site Prep | C39: 0 | D39: 0 | E39: {=D39-C39} -> 0 | F39: - | G39: - | H39: 0
B40: Drainage | C40: 0 | D40: 0 | E40: {=D40-C40} -> 0 | F40: - | G40: - | H40: 0
B41: Walls | C41: 0 | D41: 0 | E41: {=D41-C41} -> 0 | F41: - | G41: - | H41: 0
B42: Grading | C42: 0 | D42: 0 | E42: {=D42-C42} -> 0 | F42: - | G42: - | H42: 0
B43: Boulders | C43: 0 | D43: 0 | E43: {=D43-C43} -> 0 | F43: - | G43: - | H43: 0
...

Sheet SERVICES
A1: Farber-Haines Residence
A2: Design and Construction Services Summary
A3: Site Plan dated 03.17.26
F5: TYPE | H5: TYPE | I5: COMPANY
A6: DESIGN SERVICES COST ESTIMATE
D8: Schematic Design (ESTIMATED) | E8: {=6480} -> 6480
D9: Design Development / Bidding (ESTIMATED) | E9: 16500
D10: Construction Documents, During (ESTIMATED) | E10: {=900000*0.02} -> 18000
D12: PROJECT TOTAL | E12: {=SUM(E7:E11)} -> 40980
A14: CONSTRUCTION COST ESTIMATE
D16: ESTIMATED CONSTRUCTION TOTAL | E16: {='BUDGET'!E177} -> 1225964.3
D18: ESTIMATED CONSTRUCTION TOTAL W/ COST SAVINGS OPTIONS | E18: {='BUDGET'!E179} -> 1026261.6
A20: PROJECT TOTALS
D22: ESTIMATED DESIGN | E22: {=E12} -> 40980
D23: ESTIMATED CONSTRUCTION | E23: {=E16} -> 1225964.3
D24: ESTIMATED PROJECT TOTAL | E24: {=SUM(E22:E23)} -> 1266944.3
D26: ESTIMATED PROJECT TOTAL W/ COST SAVINGS OPTIONS | E26: {=E18+E22} -> 1067241.6

Sheet NOTES
A1: Farber-Haines Residence
A2: Budget Notes
A3: Site Plan dated 03.17.26
A6: EXCLUSIONS
A7: Budget does not include: Furniture, Rough Grading, Landscape Maintenance, Subgrade Drainage, Snowmelt Equipment and Install, Third Party Inspections, Tree Removal, or anything not explicitly stated above.
A9: NOTES
A10: 1.0 This budget has been prepared based off of the plans dated in the title. Assumes site will be delivered in a clean and orderly manner. Due to inflation and tariffs, pricing is subject to change throughout the course of construction and will be billed at actual price incurred for completed work. Due to the increased demand for imported goods as well as global supply chain issues, any ordered products and materials are subject to long lead times that may change over the course of the project, therefore any delivery date provided on orders are to be viewed as an approximate target date and cannot be guaranteed. Does not include Landscape Maintenance. Pricing is based off yearly averages as observed by Marpa Landscape Architecture and may vary compared to firm bids. The plans referenced are at a Schematic Design level, therefore there is the possibility for unknown details, as well as additional unknown / unidentified costs. This document is not a firm bid and is not to be used for contracts or construction. Marpa Recommends a 10% contingency is planned upon by the homeowner for unforeseen events which occur during the installation process. 2.0 Assumes use of driveway for access. Assumes job trailer can be parked on site. Does not include street occupancy or parking permits if needed. Marpa is not liable for regular wear and tear to public right of way (roads, alleys, sidewalks, etc.) that are necessary to use for access to the project. Transplanting existing trees is a risky process, with typically 50% success rate. Transplanted trees are not covered under warranty. Does not include permit or tax reconciliation fees that may be required by the relevant government authority after the completion of the Project. 3.0 Actual boulder size and locations will vary from plan, based on selection available at quarry / landscape yard. Trips to select boulders are subject to mileage reimbursement at the current IRS Standard Mileage Rate. 4.0 Sand-Finish concrete requires at least 3-4 continuous nights of temperatures above 45° to pour and cure. Control joints to be cut into concrete per the plans to help control the areas in which concrete is likely to crack, not prevent cracking. Hairline cracks may appear outside of the control joints. The presence of a hairline crack does not mean the installation was done improperly, nor does it indicate a flaw in the concrete or structural issues. The use of snow melt products on finished concrete will cause corrosion within the layers of concrete, resulting in pitting and cracking; any damage resulting from the use of snow melt products is not covered by warranty. 5.0 Sod requires minimum 2 weeks to set with no traffic of any kind. All warranties on sod, which is planted between September and April, will be considered waived, voided, and null unless the Client agrees to have the Contractor perform winter watering services as needed during the winter months while irrigation systems are winterized. 6.0 Irrigation pricing assumes points of connection, electrical and WiFi will be provided by other. Assumes controllers are to be wall mounted in the same location as the points of connection, unless otherwise noted. Final design and pressure at POCs at time of installation may affect final price. Does not include irrigation winterization and / or start up during the season following installation. 7.0 Assumes outlets to be provided at house for lighting transformer. Integration of lighting into house to be under the House Contractor’s scope. Homeowner to assume responsibility should lighting plan not be dark sky compliant. 8.0 Plant species, quantities, and size are subject to change based on availability at time of planting, as well as creative direction from Landscape Architect. Trips to select plant material are subject to mileage reimbursement at the current IRS Standard Mileage Rate. Planting window for grasses, perennials, and shrubs is after last frost in the spring and before first frost in the fall. All warranties on plant material will be considered waived, voided, and null unless the Client agrees to have the Contractor perform winter watering services as needed during the winter months while irrigation systems are winterized. 9.0 Additional cost may be required for: tenting and / or heating at time of plaster (pending cold weather temperatures), dewatering and perimeter drain (if ground water is encountered during excavation). 10.0 Allowances are rough estimates for cost of work. Actual prices will be furnished at time of invoicing. 11.0 Rough Budget Contingency is included to cover unforeseen details and costs, as the plans are not at a Construction Document level. This cost is a percentage calculation and meant to convey that, though thorough, this document may be missing costs in certain areas. 12.0 Add Options are not included in the Project Total or scope of work. Should they be added to the scope, they will be presented as a Change Order and include a Marpa Design & Planning, Oversight, Quality Control & Contracting Fee.
